---
title: Promise API的使用大全
date: 2022-08-31 17:04:43
permalink: /pages/f38dc6/
tags: 
  - 
---

## 异步请求的处理方式

从一个实际的例子来入手，调用一个函数，在这个函数中使用模拟定时器发送网络请求

- 如果发送网络请求成功了，那么告知调用者发送成功，并且将相关数据返回过去；
- 如果发送网络请求失败了，那么告知调用者发送失败，并且告知错误信息；

```js
function requestData(url) {
  setTimeout(() => {
    if (url === 'https://www.baidu.com/') {
      // 发送成功了
      successCallback('一组成功数据');
    } else {
      // 发送失败了
      failtureCallback('请求url失败');
    }
  }, 1000);
}
```

## 什么是Promise呢

在上面的解决方案中，的确可以解决请求函数得到结果之后，获取到对应的回调，并执行，但是它存在两个主要的问题。

- 第一：需要开发者自己设计回调函数、回调函数的名称、回调函数的使用等；
- 第二：对于不同的开发者，不同的框架设计出来的方案是不同的，使用者必须要去看封装回调函数的源码或者文档等，才能知道这个函数怎么调用。

那么就需要Promise API更好的帮我们解决上面的问题。

- Promise是一个类，可以翻译成承诺、许诺等；
- 需要给调用者一个承诺：延时过后会给你回调数据时，就可以创建一个Promise对象；
- 通过 new 创建 Promise 对象时，需要传入一个回调函数，称它为 executor
  - 这个回调函数会被立即执行，并且传入另外两个回调函数**resolve、reject**；
  - 调用 resolve回调函数时，会执行Promise对象的then方法传入的回调函数；
  - 调用 reject 回调函数时，会执行 Promise 对象的 catch 方法传入的回调函数；

## Promise的代码结构

```js
const promise = new Promise((resolve, reject) => {
  // 调用resolve，会执行then中的回调函数
  resolve('成功了');
  // 调用reject，会执行catch中的回调函数
  reject('错误信息');
})

promise.then(res => {
  console.log(res);
}).catch(err => {
  console.log(err);
})
```

上面Promise使用过程，我们可以将它划分成三个状态：

- *待定（pending）*: 初始状态，既没有被兑现，也没有被拒绝；
  - 当执行executor中的代码时，处于该状态；
- *已兑现（fulfilled）*: 意味着操作成功完成；
  - 执行了resolve时，处于该状态；
- *已拒绝（rejected）*: 意味着操作失败；
  - 执行了reject时，处于该状态；

## Promise重构异步请求

```js
function requestData(url) {
  return new Promise((resolve, reject) => {
    setTimeout(() => {
      if (url === 'https://www.baidu.com/') {
        // 发送成功了
        resolve('一组成功数据');
      } else {
        // 发送失败了
        reject('请求url失败');
      }
    }, 1000);
	})
}
```

## Promise的结构拆分

### Executor

Executor是在创建Promise时需要传入的一个回调函数，这个回调函数会被立即执行，并且传入两个参数：

```js
new Promise((resolve, reject) => {
	console.log("executor代码")
})
```

通常我们会在Executor中确定我们的Promise状态：

- 通过resolve，可以兑现（fulfilled）Promise的状态，我们也可以称之为已决议（resolved）；
- 通过reject，可以拒绝（reject）Promise的状态;

**一旦状态被确定下来，Promise的状态会被锁死，该Promise的状态是不可更改的**。

- 在我们调用`resolve`的时候，如果`resolv传入的值本身不是一个`Promise`，那么会将该Promise的状态变成兑现（fulfilled）；
- 在之后我们去调用reject时，已经不会有任何的响应了（**并不是这行代码不会执行，而是无法改变Promise状态**）；

### resolve不同值的区别

- **情况一**：如果resolve传入一个普通的值或者对象，那么这个值会作为then回调的参数；

  ```js
  new Promise((resolve, reject) => {
    resolve('normal value');
  }).then(res => {
    console.log('res', res); // normal value
  })
  ```

- **情况二**：如果resolve中传入的是另外一个Promise，那么这个新Promise会决定原Promise的状态： 

  ```js
  new Promise((resolve, reject) => {
    resolve(new Promise(resolve, reject) => {
      setTimeout(_ => {
        resolve('第二个Promise的resolve');
      }, 3000);
    })
  }).then(res => {
    console.log('res', res); // 第二个Promise的resolve
  }).catch(err => {
    console.log('err', err);
  });
  ```

- **情况三**：如果resolve中传入的是一个对象，并且这个对象有实现then方法，那么会执行该then方法，并且根据then方法的结果来决定Promise的状态：

  ```js
  new Promise((resolve, reject) => {
    resolve({
      then: function(resolve, reject) {
        resolve('thenable value');
      }
    })
  }).then(res => {
    console.log(res); // thenable value
  })
  ```

## Promise.prototype.then

### then方法 - 接受两个参数

then方法是**Promise实例对象**上的一个方法：它其实是放在Promise的原型上的 **Promise.prototype.then**

> 实例方法：不能通过类直接访问，需要通过该类声明的实例才能访问
>
> 类方法：通过类直接访问，不需要通过声明类的实例来访问

then方法接受两个参数：

- fulfilled的回调函数：当状态变成fulfilled时会回调的函数；
- reject的回调函数：当状态变成reject时会回调的函数；

```js
promise.then(res => {
	console.log('res:', res);
}, err => {
  console.log('err:', err);
})
// 等价于
promise.then(res => {
  console.log('res:', res);
}).catch(err => {
  console.log('err:', err);
})
```

### then方法 - 多次调用（链式调用）

同一个Promise的then方法是可以被多次调用的，当executor里的resolve方法被回调时，所有then方法里传入的回调函数都会被调用。

**当Promise的状态变成fulfilled的时候，这些回调函数都会被执行**。

```js
const promise = new Promise((resolve, reject) => {
  resolve("xxx")
})

promise.then(res => {
	console.log('res1:', res);
})

promise.then(res => {
	console.log('res2:', res);
})

promise.then(res => {
	console.log('res3:', res);
})
```

### then方法 - 返回值

then方法本身是有返回值的，它的返回值是一个Promise，所以我们可以进行如下的链式调用。

then方法里返回的**promise**有三种状态，它们分别是：

- **状态一**：当then方法中的回调函数本身在执行的时候，那么它处于pending状态；
  - 也就是executor里逻辑代码的执行。

- **状态二**： 当then方法中的回调函数返回一个结果时，那么它处于fulfilled状态，并且会将结果作为resolve的参数；
  - **情况一**：返回一个普通的值（数值/字符串/普通对象/undefined）；
  - **情况二**：返回一个Promise； 
  - **情况三**：返回一个thenable值； 

- **状态三**： 当then方法抛出一个异常时，那么它处于reject状态；

**链式调用**的核心是promise成功或失败的回调函数的返回值，可以传递到下一层的then方法中。

```js
const promise = new Promise((resolve, reject) => {
  resolve("xxx")
});

// 返回值是普通值
promise.then(res => {
  return "aaaaaa";
}).then(res => {
  console.log("res:", res); // aaaaaa
  return "bbbbbb";
})

// 返回值是一个Promise
promise.then(res => {
  return new Promise((resolve, reject) => {
    setTimeout(() => {
      resolve('111111');
    }, 3000);
  })
}).then(res => {
  console.log("res:", res); // 111111
})

// 返回值是一个对象，并且该对象实现了thenable
promise.then(res => {
  return {
    then: function(resolve, reject) {
      resolve(222222);
    }
  }
}).then(res => {
  console.log("res:", res); // 222222
})
```

## Promise.prototype.catch

`catch`方法是`Promise`实例对象上的一个方法：它其实是放在Promise的原型上的`Promise.prototype.catch`。

当executor抛出异常时，会调用**错误/拒绝**捕获的回调函数。

```js
const promise = new Promise((resolve, reject) => {
  reject("rejected status")
  // throw new Error("rejected status")
})

promise.then(undefined, err => {
  console.log("err:", err); // rejected status
})
```



也可以通过catch方法传入 **错误/拒绝** 捕获的回调函数。

```js
promise.catch(err => {
	console.log('err', err);
})
```

当第一个promise实例变成成功态时，它会执行then方法中成功的回调函数，但如果成功时的回调函数返回结果仍然是一个Promise，并抛出了异常，则同样可以被catch捕获到。

```js
const promise = new Promise((resolve, reject) => {
  resolve("resolved status");
})

promise.then(res => {
  // return new Promise((resolve, reject) => {
  //   reject("then rejected status")
  // })
  throw new Error("error message")
}).catch(err => {
  console.log("err:", err)
})
```

**注意**：`Promise.then().catch()`会优先捕获前一个promise的异常，如果发现前一个promise没有异常，则会捕获promise.then中的promise异常，如果都没有，则不会执行catch回调。`catch`方法总会优先捕获前一个`promise`的异常。

### catch方法 - 多次调用

同一个Promise的catch方法是可以被多次调用的，当当Promise的状态变成reject的时候，这些回调函数都会被执行。因为**它们之间都是相互独立且互不影响的**。

```js
promise.catch(err => {
	console.log('err', err);
})

promise.catch(err => {
	console.log('err', err);
})
```

### catch方法 - 返回值

事实上`catch`方法也是可以有返回值的，如果返回一个普通值，则也会认为是返回一个promise对象，所以catch方法后面可以继续调用then方法或catch方法的。

```js
const promise = new Promise((resolve, reject) => {
  reject("111111");
});

promise.catch(err => {
  console.log("err:", err) // 111111
  return "catch return value"
}).then(res => {
  console.log("res result:", res); // catch return value
});
```

那么如果需要后续继续执行catch，那么需要抛出一个异常。

## Promise.prototype.finally

finally是在ES9（ES2018）中新增的一个特性：表示无论Promise对象无论变成fulfilled还是reject状态，最终都会被执行的代码。 

finally方法是不接收参数的，因为无论前面是fulfilled状态，还是reject状态，它都会执行。

```js
const promise = new Promise((resolve, reject) => {
  resolve("resolve message");
});

promise.then(res => {
  console.log("res:", res); // resolve message
}).finally(() => {
  console.log("finally code execute"); // finally code execute
})
```

往往用于在finally方法里做一些promise执行完毕后的清除工作。

## Promise.resolve

前面学习的then、catch、finally方法都属于Promise的实例方法，都是存放在Promise的prototype上的。

有时候我们已经有一个现成的内容了，希望将其转成Promise来使用，这个时候我们可以使用 Promise.resolve 方法来完成。 

```js
// 普通的值
const promise = Promise.resolve({ name: "why" });
// 相当于
const promise2 = new Promise((resolve, reject) => {
  resolve({ name: "why" })
});
```

`Promise.resolve`的用法相当于new Promise，并且执行resolve操作。

resolve参数也有**三种情况**，分别是普通的值或对象，参数本身是Promise，还有可能是一个thenable。

## Promise.reject

reject方法类似于resolve方法，只是会将Promise对象的状态设置为reject状态。

Promise.reject的用法相当于new Promise，只是会调用reject： 

```js
const promise = Promise.reject("rejected message");
// 相当于
const promise2 = new Promsie((resolve, reject) => {
  reject("rejected message");
})
```

**注意：无论传入什么值都是一样的**

```js
const promise = Promise.reject({
  then: function(resolve, reject) {
    resolve('1111');
  }
})

const promise = Promise.reject(new Promise(() => {})); // err: Promise { <pending> }

promise.then(res => {
  console.log("res:", res);
}).catch(err => {
  console.log("err:", err); // err: { then: [Function: then] }
})
```

## Promise.all

它的作用是将多个Promise包裹在一起形成一个新的Promise。新的Promise状态由包裹的所有Promise共同决定。

- 当所有的Promise状态变成fulfilled状态时，新的Promise状态为fulfilled，并且会将所有Promise的返回值 组成一个数组；

  ```js
  const p1 = new Promise((resolve, reject) => {
    setTimeout(() => {
      resolve(111)
    }, 1000);
  });
  const p2 = new Promise((resolve, reject) => {
    setTimeout(() => {
      resolve(222)
    }, 1000);
  });
  const p3 = new Promise((resolve, reject) => {
    setTimeout(() => {
      resolve(333)
    }, 1000);
  });
  
  Promise.all([p2, p1, p3, "aaaa"]).then(res => {
    console.log(res); // [ 111, 222, 333, 'aaaa' ]
  })
  ```

- 当有一个Promise状态为reject时，新的Promise状态为reject，并且会将第一个reject的返回值作为参数；

  ```js
  const p1 = ...
  const p2 = new Promise((resolve, reject) => {
    setTimeout(() => {
      reject(222)
    }, 1000);
  });
  const p3 = ...
  
  Promise.all([p2, p1, p3, "aaaa"]).catch(err => {
    console.log("err:", err); // err: 22222
  })
  ```

==all方法有一个缺陷：当有其中一个Promise变成reject状态时，新Promise就会立即变成对应的reject状态==，那么对于resolved的，以及依然处于pending状态的Promise，我们是获取不到对应的结果的。

## Promise.allSettled

在ES11（ES2020）中，添加了新的API Promise.allSettled。

- 该方法会在所有的Promise都有结果（settled），无论是fulfilled，还是reject时，才会有最终的状态；
- 并且这个Promise的结果一定是fulfilled的；

```js
const p1 = new Promise((resolve, reject) => {
  setTimeout(() => {
    resolve(111)
  }, 1000);
});
const p2 = new Promise((resolve, reject) => {
  setTimeout(() => {
    reject(222)
  }, 1000);
});
const p3 = new Promise((resolve, reject) => {
  setTimeout(() => {
    resolve(333)
  }, 1000);
});

Promise.allSettled([p1, p2, p3]).then(res => {
  console.log(res);
})
/*
	[
    { status: 'fulfilled', value: 111 },
    { status: 'rejected', reason: 222 },
    { status: 'fulfilled', value: 333 }
	]
*/
```

`allSettled`的返回值是一个**数组**，数组中存放着每一个`Promise`的结果，并且是对应每一个对象的`Promise结果`，返回值的数组中是其中的每个对象，包含`status`状态，以及对应的`value`值。

## Promise.race

只要有一个Promise变成fulfilled状态，那么就结束。

```js
const p1 = new Promise((resolve, reject) => {
  setTimeout(() => {
    resolve(111)
  }, 500);
});
const p2 = new Promise((resolve, reject) => {
  setTimeout(() => {
    resolve(222)
  }, 1000);
});
const p3 = new Promise((resolve, reject) => {
  setTimeout(() => {
    resolve(333)
  }, 1000);
});

Promise.race([p1, p2, p3]).then(res => {
  console.log("res:", res); // res: 111
});
```

也有一种**意外**发生，就是rejected状态的Promise先执行完毕，最快完成，则会优先抛出这个异常。

```js
const p1 = new Promise((resolve, reject) => {
  setTimeout(() => {
    resolve(111)
  }, 1000);
});
const p2 = new Promise((resolve, reject) => {
  setTimeout(() => {
    reject(222)
  }, 500);
});
const p3 = new Promise((resolve, reject) => {
  setTimeout(() => {
    resolve(333)
  }, 2000);
});

Promise.race([p1, p2, p3]).then(res => {
  console.log("res:", res);
}).catch(err => {
  console.log("err:", err); // err:222
})
```

## Promise.any

any方法是ES12中新增的方法，和race方法是类似的：

- any方法会等到一个fulfilled状态，才会决定新Promise的状态；

  ```js
  const p1 = new Promise((resolve, reject) => {
    setTimeout(() => {
      resolve(111)
    }, 1000);
  });
  const p2 = new Promise((resolve, reject) => {
    setTimeout(() => {
      reject(222)
    }, 500);
  });
  const p3 = new Promise((resolve, reject) => {
    setTimeout(() => {
      resolve(333)
    }, 2000);
  });
  
  Promise.race([p1, p2, p3]).then(res => {
    console.log("res:", res); // res:111
  }).catch(err => {
    console.log("err:", err);
  })
  ```

- 如果所有的Promise都是reject的，那么也会等到所有的Promise都变成rejected状态；

  ```js
  const p1 = new Promise((resolve, reject) => {
    setTimeout(() => {
      reject(111)
    }, 1000);
  });
  const p2 = new Promise((resolve, reject) => {
    setTimeout(() => {
      reject(222)
    }, 500);
  });
  const p3 = new Promise((resolve, reject) => {
    setTimeout(() => {
      reject(333)
    }, 2000);
  });
  
  Promise.any([p1, p2, p3]).catch(err => {
    // 可以拿到错误信息
    console.log("err:", err.errors); // err:[111, 222, 333]
  })
  ```

  如果所有的Promise都是reject的，那么会报一个AggregateError的错误。